data/output/ADEN.txt
PASSIVE SELL 2100.00 @ 120.27
PASSIVE BUY 2220.00 @ 119.90
PASSIVE SELL 1260.00 @ 120.12
PASSIVE SELL 1180.00 @ 119.99
PASSIVE BUY 2940.00 @ 119.89
PASSIVE SELL 500.00 @ 120.03
PASSIVE BUY 2340.00 @ 119.82
PASSIVE SELL 380.00 @ 119.91
PASSIVE SELL 1620.00 @ 119.92
PASSIVE BUY 2940.00 @ 119.80
AGGRESSIVE BUY 2300.00 @ 119.97
AGGRESSIVE BUY 1740.00 @ 120.11
PASSIVE BUY 1460.00 @ 120.00
CANCEL BUY 2220.00 @ 119.90
CANCEL BUY 2940.00 @ 119.89
CANCEL BUY 2340.00 @ 119.82
CANCEL BUY 2940.00 @ 119.80
CANCEL BUY 300.00 @ 119.97
CANCEL BUY 60.00 @ 120.11
CANCEL BUY 1460.00 @ 120.00
PASSIVE BUY 2260.00 @ 120.10
AGGRESSIVE SELL 1660.00 @ 120.10
PASSIVE SELL 740.00 @ 120.12
PASSIVE BUY 1220.00 @ 120.01
PASSIVE BUY 780.00 @ 119.97
PASSIVE SELL 1420.00 @ 120.26
AGGRESSIVE SELL 2260.00 @ 119.97
PASSIVE BUY 1460.00 @ 119.86
AGGRESSIVE BUY 780.00 @ 120.12
PASSIVE SELL 1460.00 @ 120.01
PASSIVE SELL 1420.00 @ 119.99
PASSIVE BUY 740.00 @ 119.97
AGGRESSIVE BUY 1620.00 @ 120.01
PASSIVE SELL 2100.00 @ 120.08
PASSIVE BUY 1860.00 @ 119.96
AGGRESSIVE SELL 1740.00 @ 119.96
AGGRESSIVE BUY 1140.00 @ 120.01
PASSIVE BUY 820.00 @ 119.88
AGGRESSIVE BUY 820.00 @ 120.04
PASSIVE BUY 2580.00 @ 119.95
AGGRESSIVE SELL 1780.00 @ 119.96
PASSIVE SELL 2020.00 @ 120.02
PASSIVE BUY 1340.00 @ 119.85
PASSIVE SELL 740.00 @ 120.01
PASSIVE BUY 1700.00 @ 119.99
AGGRESSIVE BUY 2180.00 @ 120.02
PASSIVE BUY 2860.00 @ 119.92
CANCEL BUY 1460.00 @ 119.86
CANCEL BUY 120.00 @ 119.96
CANCEL BUY 820.00 @ 119.88
CANCEL BUY 2580.00 @ 119.95
CANCEL BUY 1340.00 @ 119.85
CANCEL BUY 1700.00 @ 119.99
CANCEL BUY 2860.00 @ 119.92
AGGRESSIVE BUY 860.00 @ 120.07
PASSIVE SELL 460.00 @ 120.13
PASSIVE SELL 1180.00 @ 120.22
AGGRESSIVE BUY 900.00 @ 120.08
PASSIVE BUY 1660.00 @ 119.98
PASSIVE BUY 1500.00 @ 120.06
PASSIVE BUY 1420.00 @ 119.95
AGGRESSIVE SELL 1460.00 @ 120.06
AGGRESSIVE BUY 2820.00 @ 120.13
PASSIVE BUY 2860.00 @ 120.06
AGGRESSIVE SELL 740.00 @ 120.06
PASSIVE SELL 460.00 @ 120.14
PASSIVE BUY 2300.00 @ 120.03
AGGRESSIVE BUY 2460.00 @ 120.19
PASSIVE BUY 1900.00 @ 120.13
AGGRESSIVE SELL 660.00 @ 120.19
PASSIVE BUY 2740.00 @ 120.08
CANCEL BUY 1660.00 @ 119.98
CANCEL BUY 1420.00 @ 119.95
CANCEL BUY 2440.00 @ 120.06
CANCEL BUY 2300.00 @ 120.03
CANCEL BUY 1280.00 @ 120.19
CANCEL BUY 1900.00 @ 120.13
CANCEL BUY 2740.00 @ 120.08
PASSIVE BUY 1180.00 @ 120.16
PASSIVE SELL 500.00 @ 120.19
PASSIVE BUY 2740.00 @ 120.12
PASSIVE SELL 1340.00 @ 120.21
PASSIVE BUY 1420.00 @ 120.09
PASSIVE SELL 1580.00 @ 120.19
AGGRESSIVE SELL 1380.00 @ 120.12
AGGRESSIVE BUY 2620.00 @ 120.21
PASSIVE SELL 1380.00 @ 120.25
AGGRESSIVE SELL 740.00 @ 120.12
PASSIVE BUY 940.00 @ 120.19
AGGRESSIVE BUY 2620.00 @ 120.24
AGGRESSIVE SELL 1580.00 @ 120.21
PASSIVE BUY 1740.00 @ 120.15
AGGRESSIVE BUY 1140.00 @ 120.25
PASSIVE SELL 1100.00 @ 120.35
AGGRESSIVE SELL 900.00 @ 120.19
PASSIVE SELL 740.00 @ 120.21
AGGRESSIVE SELL 2060.00 @ 120.12
PASSIVE SELL 1420.00 @ 120.27
AGGRESSIVE BUY 1740.00 @ 120.25
PASSIVE SELL 1140.00 @ 120.29
PASSIVE BUY 1740.00 @ 120.01
PASSIVE SELL 980.00 @ 120.19
PASSIVE BUY 820.00 @ 120.14
AGGRESSIVE BUY 2180.00 @ 120.25
PASSIVE SELL 1420.00 @ 120.29
AGGRESSIVE BUY 1380.00 @ 120.26
PASSIVE SELL 700.00 @ 120.33
PASSIVE SELL 1580.00 @ 120.30
PASSIVE BUY 1740.00 @ 120.20
AGGRESSIVE SELL 780.00 @ 120.25
PASSIVE SELL 460.00 @ 120.29
AGGRESSIVE BUY 2820.00 @ 120.27
PASSIVE BUY 780.00 @ 120.14
AGGRESSIVE BUY 1220.00 @ 120.29
PASSIVE BUY 820.00 @ 120.20
AGGRESSIVE BUY 980.00 @ 120.29
AGGRESSIVE SELL 1220.00 @ 120.21
AGGRESSIVE BUY 2540.00 @ 120.27
PASSIVE BUY 2140.00 @ 120.21
CANCEL BUY 1520.00 @ 120.12
CANCEL BUY 1420.00 @ 120.09
CANCEL BUY 1740.00 @ 120.01
CANCEL BUY -820.00 @ 120.14
CANCEL BUY -1740.00 @ 120.20
CANCEL BUY 780.00 @ 120.14
CANCEL BUY 820.00 @ 120.20
CANCEL BUY 1560.00 @ 120.27
CANCEL BUY 2140.00 @ 120.21
AGGRESSIVE BUY 820.00 @ 120.29
PASSIVE SELL 2020.00 @ 120.33
PASSIVE SELL 1180.00 @ 120.30
PASSIVE SELL 1060.00 @ 120.30
PASSIVE BUY 2820.00 @ 120.27
PASSIVE SELL 1420.00 @ 120.29
AGGRESSIVE SELL 700.00 @ 120.27
AGGRESSIVE SELL 1220.00 @ 120.27
AGGRESSIVE SELL 2180.00 @ 120.23
PASSIVE SELL 2220.00 @ 120.28
PASSIVE BUY 1500.00 @ 120.11
PASSIVE BUY 2660.00 @ 120.09
PASSIVE SELL 1620.00 @ 120.25
CANCEL SELL 1100.00 @ 120.35
PASSIVE SELL 1740.00 @ 120.13
CANCEL SELL -700.00 @ 120.33
CANCEL SELL 2020.00 @ 120.33
AGGRESSIVE BUY 900.00 @ 120.13
PASSIVE SELL 620.00 @ 120.18
CANCEL SELL -1580.00 @ 120.30
CANCEL SELL -1180.00 @ 120.30
CANCEL SELL 1060.00 @ 120.30
PASSIVE BUY 1540.00 @ 120.05
PASSIVE BUY 2140.00 @ 120.08
AGGRESSIVE BUY 740.00 @ 120.13
PASSIVE BUY 1340.00 @ 120.11
AGGRESSIVE BUY 740.00 @ 120.21
PASSIVE BUY 1060.00 @ 120.19
PASSIVE BUY 1420.00 @ 120.22
CANCEL BUY -1500.00 @ 120.11
CANCEL BUY 2660.00 @ 120.09
CANCEL BUY 1540.00 @ 120.05
CANCEL BUY 2140.00 @ 120.08
CANCEL BUY 1340.00 @ 120.11
CANCEL BUY 20.00 @ 120.21
CANCEL BUY 1060.00 @ 120.19
CANCEL BUY 1420.00 @ 120.22
PASSIVE BUY 2420.00 @ 120.06
PASSIVE SELL 940.00 @ 120.30
PASSIVE BUY 1740.00 @ 120.11
PASSIVE SELL 820.00 @ 120.24
PASSIVE BUY 1580.00 @ 120.16
AGGRESSIVE BUY 1940.00 @ 120.24
AGGRESSIVE BUY 2140.00 @ 120.28
PASSIVE BUY 2540.00 @ 120.24
AGGRESSIVE BUY 1900.00 @ 120.29
AGGRESSIVE SELL 2300.00 @ 120.24
AGGRESSIVE SELL 2220.00 @ 120.22
AGGRESSIVE SELL 1220.00 @ 120.16
AGGRESSIVE BUY 2140.00 @ 120.29
PASSIVE BUY 1780.00 @ 120.10
PASSIVE BUY 1140.00 @ 120.04
PASSIVE BUY 820.00 @ 120.18
PASSIVE BUY 940.00 @ 120.06
PASSIVE BUY 1300.00 @ 120.19
CANCEL BUY -2420.00 @ 120.06
CANCEL BUY 1740.00 @ 120.11
CANCEL BUY 360.00 @ 120.16
CANCEL BUY 1780.00 @ 120.10
CANCEL BUY 1140.00 @ 120.04
CANCEL BUY 820.00 @ 120.18
CANCEL BUY 940.00 @ 120.06
CANCEL BUY 1300.00 @ 120.19
PASSIVE SELL 2260.00 @ 120.32
PASSIVE SELL 740.00 @ 120.23
PASSIVE SELL 2140.00 @ 120.06
AGGRESSIVE BUY 820.00 @ 120.06
PASSIVE SELL 1220.00 @ 119.99
AGGRESSIVE BUY 780.00 @ 119.99
AGGRESSIVE BUY 1300.00 @ 120.06
AGGRESSIVE BUY 2940.00 @ 120.29
PASSIVE BUY 1260.00 @ 120.16
PASSIVE BUY 1860.00 @ 120.05
PASSIVE BUY 820.00 @ 120.20
AGGRESSIVE BUY 2420.00 @ 120.30
AGGRESSIVE BUY 2660.00 @ 120.44
PASSIVE BUY 2740.00 @ 120.44
PASSIVE BUY 2860.00 @ 120.48
PASSIVE SELL 1100.00 @ 120.52
AGGRESSIVE BUY 2420.00 @ 120.52
CANCEL BUY 1260.00 @ 120.16
CANCEL BUY 1860.00 @ 120.05
CANCEL BUY 820.00 @ 120.20
CANCEL BUY 1260.00 @ 120.30
CANCEL BUY -400.00 @ 120.44
CANCEL BUY 2740.00 @ 120.44
CANCEL BUY 2860.00 @ 120.48
CANCEL BUY 1320.00 @ 120.52
PASSIVE BUY 2100.00 @ 119.89
PASSIVE BUY 2100.00 @ 119.84
PASSIVE BUY 1780.00 @ 120.05
PASSIVE SELL 1460.00 @ 120.72
PASSIVE BUY 2620.00 @ 120.04
PASSIVE BUY 1380.00 @ 120.08
PASSIVE BUY 2260.00 @ 120.15
PASSIVE SELL 780.00 @ 120.68
PASSIVE BUY 1900.00 @ 120.32
CANCEL BUY 2100.00 @ 119.89
CANCEL BUY 2100.00 @ 119.84
CANCEL BUY 1780.00 @ 120.05
CANCEL BUY 2620.00 @ 120.04
CANCEL BUY 1380.00 @ 120.08
CANCEL BUY 2260.00 @ 120.15
CANCEL BUY 1900.00 @ 120.32
PASSIVE BUY 1060.00 @ 120.49
PASSIVE SELL 700.00 @ 120.54
AGGRESSIVE SELL 380.00 @ 120.49
PASSIVE BUY 2180.00 @ 120.43
PASSIVE SELL 980.00 @ 120.53
AGGRESSIVE SELL 2180.00 @ 120.44
PASSIVE SELL 380.00 @ 120.56
AGGRESSIVE BUY 1660.00 @ 120.53
AGGRESSIVE BUY 860.00 @ 120.53
PASSIVE BUY 2020.00 @ 120.47
PASSIVE SELL 2020.00 @ 120.62
PASSIVE BUY 2100.00 @ 120.49
AGGRESSIVE BUY 1740.00 @ 120.56
PASSIVE SELL 1260.00 @ 120.63
PASSIVE SELL 1820.00 @ 120.66
PASSIVE SELL 2220.00 @ 120.70
AGGRESSIVE BUY 2660.00 @ 120.63
AGGRESSIVE SELL 1660.00 @ 120.55
AGGRESSIVE BUY 1020.00 @ 120.57
AGGRESSIVE SELL 540.00 @ 120.54
PASSIVE SELL 1340.00 @ 120.55
CANCEL SELL 1460.00 @ 120.72
AGGRESSIVE BUY 2140.00 @ 120.57
AGGRESSIVE BUY 2140.00 @ 120.66
AGGRESSIVE BUY 1740.00 @ 120.70
PASSIVE BUY 2300.00 @ 120.62
AGGRESSIVE BUY 1540.00 @ 120.70
AGGRESSIVE SELL 1660.00 @ 120.62
AGGRESSIVE BUY 1100.00 @ 120.78
CANCEL BUY 2180.00 @ 120.43
CANCEL BUY 40.00 @ 120.53
CANCEL BUY 2020.00 @ 120.47
CANCEL BUY 2100.00 @ 120.49
CANCEL BUY 280.00 @ 120.57
CANCEL BUY 640.00 @ 120.62
CANCEL BUY 1080.00 @ 120.78
PASSIVE SELL 1380.00 @ 120.73
PASSIVE SELL 1780.00 @ 120.55
PASSIVE SELL 1500.00 @ 120.37
