data/output/CFR.txt
PASSIVE SELL 1020.00 @ 360.05
PASSIVE BUY 2900.00 @ 359.92
PASSIVE BUY 1180.00 @ 359.89
PASSIVE BUY 1300.00 @ 359.94
AGGRESSIVE SELL 1700.00 @ 359.92
PASSIVE BUY 1820.00 @ 359.96
PASSIVE BUY 1500.00 @ 359.84
PASSIVE BUY 980.00 @ 359.97
PASSIVE BUY 860.00 @ 360.01
PASSIVE BUY 1260.00 @ 360.00
CANCEL BUY 2500.00 @ 359.92
CANCEL BUY 1180.00 @ 359.89
CANCEL BUY 1820.00 @ 359.96
CANCEL BUY 1500.00 @ 359.84
CANCEL BUY 980.00 @ 359.97
CANCEL BUY 860.00 @ 360.01
CANCEL BUY 1260.00 @ 360.00
PASSIVE SELL 1100.00 @ 359.91
PASSIVE SELL 380.00 @ 359.89
AGGRESSIVE BUY 1620.00 @ 360.03
AGGRESSIVE BUY 1340.00 @ 360.17
AGGRESSIVE SELL 1660.00 @ 360.16
PASSIVE SELL 700.00 @ 360.07
PASSIVE SELL 1060.00 @ 360.10
PASSIVE SELL 1100.00 @ 360.15
PASSIVE BUY 1540.00 @ 360.02
AGGRESSIVE SELL 1900.00 @ 359.95
PASSIVE SELL 940.00 @ 360.06
PASSIVE SELL 980.00 @ 359.93
CANCEL SELL 1340.00 @ 360.16
PASSIVE BUY 2940.00 @ 359.75
PASSIVE SELL 1060.00 @ 359.83
CANCEL SELL 1100.00 @ 360.15
PASSIVE SELL 1940.00 @ 359.83
AGGRESSIVE SELL 660.00 @ 359.75
AGGRESSIVE BUY 1780.00 @ 359.83
PASSIVE BUY 1260.00 @ 359.71
AGGRESSIVE SELL 2220.00 @ 359.75
AGGRESSIVE SELL 1060.00 @ 359.73
CANCEL SELL 1060.00 @ 360.10
PASSIVE SELL 1140.00 @ 359.79
CANCEL SELL 700.00 @ 360.07
AGGRESSIVE SELL 2140.00 @ 359.71
CANCEL SELL 940.00 @ 360.06
PASSIVE SELL 2060.00 @ 359.80
CANCEL SELL 220.00 @ 359.95
AGGRESSIVE BUY 1700.00 @ 359.73
PASSIVE SELL 1540.00 @ 359.60
PASSIVE SELL 1340.00 @ 359.45
CANCEL SELL 980.00 @ 359.93
AGGRESSIVE BUY 2300.00 @ 359.58
AGGRESSIVE BUY 2860.00 @ 359.62
PASSIVE SELL 1260.00 @ 359.78
PASSIVE SELL 2300.00 @ 359.69
AGGRESSIVE BUY 940.00 @ 359.69
PASSIVE SELL 1580.00 @ 359.65
CANCEL SELL 1220.00 @ 359.83
AGGRESSIVE SELL 1660.00 @ 359.59
CANCEL SELL 2060.00 @ 359.80
AGGRESSIVE SELL 740.00 @ 359.58
PASSIVE SELL 1580.00 @ 359.69
PASSIVE SELL 2300.00 @ 359.65
PASSIVE BUY 980.00 @ 359.48
AGGRESSIVE SELL 2140.00 @ 359.56
CANCEL SELL 1140.00 @ 359.79
PASSIVE SELL 2260.00 @ 359.62
CANCEL SELL 1260.00 @ 359.78
PASSIVE BUY 2180.00 @ 359.43
AGGRESSIVE BUY 2500.00 @ 359.59
AGGRESSIVE SELL 1220.00 @ 359.48
PASSIVE SELL 1420.00 @ 359.56
PASSIVE BUY 2380.00 @ 359.47
PASSIVE BUY 2460.00 @ 359.54
AGGRESSIVE BUY 1420.00 @ 359.56
PASSIVE SELL 1660.00 @ 359.69
PASSIVE BUY 2500.00 @ 359.43
AGGRESSIVE BUY 1460.00 @ 359.62
PASSIVE SELL 1060.00 @ 359.56
PASSIVE BUY 1980.00 @ 359.46
PASSIVE BUY 1660.00 @ 359.41
PASSIVE SELL 1620.00 @ 359.63
AGGRESSIVE BUY 2780.00 @ 359.62
PASSIVE SELL 540.00 @ 359.64
AGGRESSIVE BUY 1660.00 @ 359.64
PASSIVE SELL 1300.00 @ 359.68
PASSIVE BUY 2500.00 @ 359.60
CANCEL BUY -2180.00 @ 359.43
CANCEL BUY 2380.00 @ 359.47
CANCEL BUY 2460.00 @ 359.54
CANCEL BUY 2500.00 @ 359.43
CANCEL BUY 1980.00 @ 359.46
CANCEL BUY 1660.00 @ 359.41
CANCEL BUY 920.00 @ 359.62
CANCEL BUY 2500.00 @ 359.60
PASSIVE BUY 980.00 @ 359.43
PASSIVE SELL 940.00 @ 359.50
AGGRESSIVE SELL 1500.00 @ 359.38
CANCEL SELL 180.00 @ 359.73
PASSIVE SELL 1140.00 @ 359.42
CANCEL SELL -1360.00 @ 359.69
CANCEL SELL -1580.00 @ 359.69
CANCEL SELL 1660.00 @ 359.69
AGGRESSIVE BUY 1940.00 @ 359.45
AGGRESSIVE SELL 1620.00 @ 359.35
AGGRESSIVE BUY 2580.00 @ 359.52
PASSIVE BUY 1420.00 @ 359.58
PASSIVE SELL 2020.00 @ 359.72
PASSIVE SELL 380.00 @ 359.74
AGGRESSIVE SELL 1860.00 @ 359.48
PASSIVE SELL 1220.00 @ 359.35
CANCEL SELL 380.00 @ 359.74
PASSIVE SELL 1060.00 @ 359.36
CANCEL SELL 2020.00 @ 359.72
PASSIVE SELL 900.00 @ 359.24
CANCEL SELL 1300.00 @ 359.68
PASSIVE SELL 1420.00 @ 359.23
CANCEL SELL -1580.00 @ 359.65
CANCEL SELL 2300.00 @ 359.65
PASSIVE SELL 1060.00 @ 359.24
AGGRESSIVE BUY 900.00 @ 359.23
AGGRESSIVE BUY 2900.00 @ 359.34
AGGRESSIVE BUY 1540.00 @ 359.36
PASSIVE BUY 2420.00 @ 359.30
PASSIVE SELL 1620.00 @ 359.44
AGGRESSIVE SELL 1700.00 @ 359.33
AGGRESSIVE BUY 1900.00 @ 359.34
AGGRESSIVE SELL 1740.00 @ 359.31
PASSIVE SELL 1180.00 @ 359.31
AGGRESSIVE BUY 2100.00 @ 359.31
PASSIVE BUY 2900.00 @ 359.26
AGGRESSIVE SELL 1420.00 @ 359.30
AGGRESSIVE SELL 820.00 @ 359.30
PASSIVE BUY 2460.00 @ 359.30
AGGRESSIVE BUY 1980.00 @ 359.38
PASSIVE BUY 1740.00 @ 359.40
AGGRESSIVE SELL 1540.00 @ 359.40
PASSIVE BUY 1380.00 @ 359.34
AGGRESSIVE SELL 1380.00 @ 359.34
AGGRESSIVE BUY 2420.00 @ 359.45
PASSIVE BUY 1820.00 @ 359.35
AGGRESSIVE SELL 2060.00 @ 359.40
PASSIVE SELL 1260.00 @ 359.46
PASSIVE SELL 700.00 @ 359.48
AGGRESSIVE BUY 1260.00 @ 359.40
AGGRESSIVE BUY 2780.00 @ 359.49
PASSIVE BUY 2700.00 @ 359.43
PASSIVE SELL 2140.00 @ 359.64
PASSIVE BUY 2220.00 @ 359.51
CANCEL BUY -180.00 @ 359.30
CANCEL BUY 2900.00 @ 359.26
CANCEL BUY 2460.00 @ 359.30
CANCEL BUY 1240.00 @ 359.34
CANCEL BUY 1820.00 @ 359.35
CANCEL BUY 680.00 @ 359.49
CANCEL BUY 2700.00 @ 359.43
CANCEL BUY 2220.00 @ 359.51
PASSIVE SELL 820.00 @ 359.56
PASSIVE BUY 1860.00 @ 359.47
PASSIVE SELL 1540.00 @ 359.62
PASSIVE SELL 980.00 @ 359.53
AGGRESSIVE SELL 1140.00 @ 359.47
PASSIVE BUY 1260.00 @ 359.47
AGGRESSIVE SELL 1540.00 @ 359.47
PASSIVE SELL 1300.00 @ 359.52
PASSIVE SELL 2100.00 @ 359.65
PASSIVE BUY 2900.00 @ 359.41
AGGRESSIVE BUY 1660.00 @ 359.53
PASSIVE SELL 1460.00 @ 359.54
AGGRESSIVE SELL 420.00 @ 359.47
PASSIVE BUY 2780.00 @ 359.44
AGGRESSIVE BUY 1500.00 @ 359.54
PASSIVE BUY 2580.00 @ 359.49
PASSIVE BUY 1980.00 @ 359.52
PASSIVE BUY 2140.00 @ 359.48
PASSIVE SELL 1580.00 @ 359.54
AGGRESSIVE BUY 1980.00 @ 359.54
AGGRESSIVE SELL 1540.00 @ 359.52
AGGRESSIVE SELL 2100.00 @ 359.49
AGGRESSIVE SELL 1500.00 @ 359.48
AGGRESSIVE SELL 2260.00 @ 359.46
AGGRESSIVE SELL 980.00 @ 359.44
PASSIVE BUY 1740.00 @ 359.31
PASSIVE BUY 1140.00 @ 359.37
AGGRESSIVE BUY 2620.00 @ 359.57
PASSIVE BUY 1740.00 @ 359.61
PASSIVE BUY 1180.00 @ 359.55
CANCEL BUY 2900.00 @ 359.41
CANCEL BUY 1800.00 @ 359.44
CANCEL BUY 1740.00 @ 359.31
CANCEL BUY 1140.00 @ 359.37
CANCEL BUY 940.00 @ 359.57
CANCEL BUY 1740.00 @ 359.61
CANCEL BUY 1180.00 @ 359.55
PASSIVE SELL 1420.00 @ 359.48
PASSIVE SELL 2060.00 @ 359.59
AGGRESSIVE BUY 2820.00 @ 359.59
AGGRESSIVE BUY 2820.00 @ 359.59
AGGRESSIVE BUY 1700.00 @ 359.64
PASSIVE BUY 2500.00 @ 359.57
PASSIVE SELL 660.00 @ 359.69
AGGRESSIVE SELL 1540.00 @ 359.59
AGGRESSIVE SELL 1340.00 @ 359.57
PASSIVE SELL 940.00 @ 359.59
AGGRESSIVE SELL 1740.00 @ 359.57
PASSIVE SELL 1100.00 @ 359.71
AGGRESSIVE BUY 1740.00 @ 359.64
PASSIVE SELL 2180.00 @ 359.69
PASSIVE SELL 380.00 @ 359.68
PASSIVE SELL 1220.00 @ 359.62
AGGRESSIVE BUY 900.00 @ 359.62
PASSIVE SELL 500.00 @ 359.62
PASSIVE BUY 1580.00 @ 359.61
AGGRESSIVE BUY 2420.00 @ 359.64
AGGRESSIVE BUY 1380.00 @ 359.65
AGGRESSIVE SELL 820.00 @ 359.61
PASSIVE BUY 2460.00 @ 359.60
AGGRESSIVE BUY 2460.00 @ 359.69
AGGRESSIVE SELL 2300.00 @ 359.60
PASSIVE SELL 620.00 @ 359.69
PASSIVE BUY 2820.00 @ 359.60
PASSIVE SELL 2300.00 @ 359.76
AGGRESSIVE BUY 1940.00 @ 359.69
PASSIVE BUY 1620.00 @ 359.57
PASSIVE SELL 2020.00 @ 359.80
PASSIVE SELL 2020.00 @ 359.77
PASSIVE BUY 2460.00 @ 359.54
PASSIVE SELL 940.00 @ 359.70
PASSIVE BUY 1900.00 @ 359.57
AGGRESSIVE SELL 620.00 @ 359.60
PASSIVE SELL 860.00 @ 359.74
CANCEL SELL 2020.00 @ 359.80
AGGRESSIVE SELL 1540.00 @ 359.60
PASSIVE SELL 1940.00 @ 359.65
CANCEL SELL 2020.00 @ 359.77
PASSIVE BUY 1980.00 @ 359.61
PASSIVE SELL 1460.00 @ 359.70
AGGRESSIVE SELL 1340.00 @ 359.61
PASSIVE SELL 700.00 @ 359.66
CANCEL SELL 2300.00 @ 359.76
PASSIVE BUY 1100.00 @ 359.61
AGGRESSIVE SELL 580.00 @ 359.61
PASSIVE SELL 2060.00 @ 359.73
CANCEL SELL 860.00 @ 359.74
PASSIVE SELL 1060.00 @ 359.73
PASSIVE SELL 1420.00 @ 359.77
CANCEL SELL 1420.00 @ 359.77
AGGRESSIVE SELL 820.00 @ 359.61
PASSIVE BUY 1020.00 @ 359.56
AGGRESSIVE BUY 1180.00 @ 359.65
AGGRESSIVE BUY 1980.00 @ 359.70
AGGRESSIVE SELL 1220.00 @ 359.60
PASSIVE SELL 460.00 @ 359.80
PASSIVE SELL 1100.00 @ 359.66
PASSIVE SELL 1940.00 @ 359.75
AGGRESSIVE BUY 2460.00 @ 359.66
AGGRESSIVE BUY 1660.00 @ 359.70
AGGRESSIVE BUY 1540.00 @ 359.71
AGGRESSIVE SELL 1500.00 @ 359.60
PASSIVE BUY 1140.00 @ 359.61
PASSIVE SELL 1420.00 @ 359.70
PASSIVE SELL 700.00 @ 359.68
PASSIVE SELL 1180.00 @ 359.72
CANCEL SELL 460.00 @ 359.80
PASSIVE SELL 380.00 @ 359.69
CANCEL SELL 1940.00 @ 359.75
PASSIVE SELL 2060.00 @ 359.70
PASSIVE BUY 2380.00 @ 359.64
